[2024-06-16T06:33:49.430+0000] {task_context_logger.py:104} ERROR - Executor reports task instance <TaskInstance: rand_request.get_request scheduled__2024-06-16T05:05:00+00:00 [queued]> finished (failed) although the task says it's queued. (Info: None) Was the task killed externally?
