[2024-06-17T08:56:53.972+0000] {task_context_logger.py:104} ERROR - Executor reports task instance <TaskInstance: postgres_to_s3.fetch_user scheduled__2024-06-16T00:00:00+00:00 [queued]> finished (failed) although the task says it's queued. (Info: None) Was the task killed externally?
