[2024-06-16T10:37:22.134+0000] {task_context_logger.py:104} ERROR - Executor reports task instance <TaskInstance: random_user_request_etl.transform scheduled__2024-06-16T01:00:00+00:00 [queued]> finished (failed) although the task says it's queued. (Info: None) Was the task killed externally?
