[2024-06-15T21:12:18.636+0000] {task_context_logger.py:104} ERROR - Executor reports task instance <TaskInstance: rand_request.load_to_s3 manual__2024-06-15T21:09:54.698888+00:00 [queued]> finished (failed) although the task says it's queued. (Info: None) Was the task killed externally?
