[2024-06-16T10:24:08.267+0000] {task_context_logger.py:104} ERROR - Executor reports task instance <TaskInstance: random_user_request_etl.fetch_user scheduled__2024-06-16T01:11:00+00:00 [queued]> finished (failed) although the task says it's queued. (Info: None) Was the task killed externally?
