[2024-06-15T09:49:21.089+0000] {task_context_logger.py:104} ERROR - Executor reports task instance <TaskInstance: csv_to_s3_dag.extract_csv manual__2024-06-15T09:48:22.159777+00:00 [queued]> finished (failed) although the task says it's queued. (Info: None) Was the task killed externally?
