[2024-06-19T05:15:49.004+0000] {local_task_job_runner.py:120} INFO - ::group::Pre task execution logs
[2024-06-19T05:15:49.027+0000] {taskinstance.py:2076} INFO - Dependencies all met for dep_context=non-requeueable deps ti=<TaskInstance: postgres_to_s3.load_to_postgres scheduled__2024-06-18T00:00:00+00:00 [queued]>
[2024-06-19T05:15:49.040+0000] {taskinstance.py:2076} INFO - Dependencies all met for dep_context=requeueable deps ti=<TaskInstance: postgres_to_s3.load_to_postgres scheduled__2024-06-18T00:00:00+00:00 [queued]>
[2024-06-19T05:15:49.041+0000] {taskinstance.py:2306} INFO - Starting attempt 1 of 6
[2024-06-19T05:15:49.170+0000] {taskinstance.py:2330} INFO - Executing <Task(PythonOperator): load_to_postgres> on 2024-06-18 00:00:00+00:00
[2024-06-19T05:15:49.183+0000] {standard_task_runner.py:90} INFO - Running: ['***', 'tasks', 'run', 'postgres_to_s3', 'load_to_postgres', 'scheduled__2024-06-18T00:00:00+00:00', '--job-id', '106', '--raw', '--subdir', 'DAGS_FOLDER/postgres_s3.py', '--cfg-path', '/tmp/tmpvvj7pmma']
[2024-06-19T05:15:49.188+0000] {standard_task_runner.py:91} INFO - Job 106: Subtask load_to_postgres
[2024-06-19T05:15:49.191+0000] {logging_mixin.py:188} WARNING - /home/***/.local/lib/python3.12/site-packages/***/task/task_runner/standard_task_runner.py:61 DeprecationWarning: This process (pid=233) is multi-threaded, use of fork() may lead to deadlocks in the child.
[2024-06-19T05:15:49.193+0000] {standard_task_runner.py:63} INFO - Started process 238 to run task
[2024-06-19T05:15:49.294+0000] {task_command.py:426} INFO - Running <TaskInstance: postgres_to_s3.load_to_postgres scheduled__2024-06-18T00:00:00+00:00 [running]> on host dc64bc371a82
[2024-06-19T05:15:49.650+0000] {taskinstance.py:2648} INFO - Exporting env vars: AIRFLOW_CTX_DAG_EMAIL='protectorateog@gmail.com' AIRFLOW_CTX_DAG_OWNER='protectorate' AIRFLOW_CTX_DAG_ID='postgres_to_s3' AIRFLOW_CTX_TASK_ID='load_to_postgres' AIRFLOW_CTX_EXECUTION_DATE='2024-06-18T00:00:00+00:00' AIRFLOW_CTX_TRY_NUMBER='1' AIRFLOW_CTX_DAG_RUN_ID='scheduled__2024-06-18T00:00:00+00:00'
[2024-06-19T05:15:49.652+0000] {taskinstance.py:430} INFO - ::endgroup::
[2024-06-19T05:15:50.755+0000] {base.py:84} INFO - Using connection ID 'post_s3' for task execution.
[2024-06-19T05:15:50.970+0000] {python.py:237} INFO - Done. Returned value was: None
[2024-06-19T05:15:50.971+0000] {taskinstance.py:441} INFO - ::group::Post task execution logs
[2024-06-19T05:15:50.983+0000] {taskinstance.py:1206} INFO - Marking task as SUCCESS. dag_id=postgres_to_s3, task_id=load_to_postgres, run_id=scheduled__2024-06-18T00:00:00+00:00, execution_date=20240618T000000, start_date=20240619T051549, end_date=20240619T051550
[2024-06-19T05:15:51.058+0000] {local_task_job_runner.py:240} INFO - Task exited with return code 0
[2024-06-19T05:15:51.085+0000] {taskinstance.py:3498} INFO - 1 downstream tasks scheduled from follow-on schedule check
[2024-06-19T05:15:51.345+0000] {local_task_job_runner.py:222} INFO - ::endgroup::
[2024-06-22T15:26:33.748+0000] {local_task_job_runner.py:120} INFO - ::group::Pre task execution logs
[2024-06-22T15:26:33.996+0000] {taskinstance.py:2076} INFO - Dependencies all met for dep_context=non-requeueable deps ti=<TaskInstance: postgres_to_s3.load_to_postgres scheduled__2024-06-18T00:00:00+00:00 [queued]>
[2024-06-22T15:26:34.010+0000] {taskinstance.py:2076} INFO - Dependencies all met for dep_context=requeueable deps ti=<TaskInstance: postgres_to_s3.load_to_postgres scheduled__2024-06-18T00:00:00+00:00 [queued]>
[2024-06-22T15:26:34.011+0000] {taskinstance.py:2306} INFO - Starting attempt 1 of 6
[2024-06-22T15:26:35.619+0000] {taskinstance.py:2330} INFO - Executing <Task(PythonOperator): load_to_postgres> on 2024-06-18 00:00:00+00:00
[2024-06-22T15:26:35.630+0000] {standard_task_runner.py:90} INFO - Running: ['***', 'tasks', 'run', 'postgres_to_s3', 'load_to_postgres', 'scheduled__2024-06-18T00:00:00+00:00', '--job-id', '23', '--raw', '--subdir', 'DAGS_FOLDER/postgres_s3.py', '--cfg-path', '/tmp/tmpnip5gp_7']
[2024-06-22T15:26:35.633+0000] {standard_task_runner.py:91} INFO - Job 23: Subtask load_to_postgres
[2024-06-22T15:26:35.636+0000] {logging_mixin.py:188} WARNING - /home/***/.local/lib/python3.12/site-packages/***/task/task_runner/standard_task_runner.py:61 DeprecationWarning: This process (pid=3909) is multi-threaded, use of fork() may lead to deadlocks in the child.
[2024-06-22T15:26:35.838+0000] {standard_task_runner.py:63} INFO - Started process 3926 to run task
[2024-06-22T15:26:38.677+0000] {task_command.py:426} INFO - Running <TaskInstance: postgres_to_s3.load_to_postgres scheduled__2024-06-18T00:00:00+00:00 [running]> on host 6380d29236af
[2024-06-22T15:26:42.539+0000] {taskinstance.py:2648} INFO - Exporting env vars: AIRFLOW_CTX_DAG_EMAIL='protectorateog@gmail.com' AIRFLOW_CTX_DAG_OWNER='protectorate' AIRFLOW_CTX_DAG_ID='postgres_to_s3' AIRFLOW_CTX_TASK_ID='load_to_postgres' AIRFLOW_CTX_EXECUTION_DATE='2024-06-18T00:00:00+00:00' AIRFLOW_CTX_TRY_NUMBER='1' AIRFLOW_CTX_DAG_RUN_ID='scheduled__2024-06-18T00:00:00+00:00'
[2024-06-22T15:26:42.541+0000] {taskinstance.py:430} INFO - ::endgroup::
[2024-06-22T15:26:53.624+0000] {base.py:84} INFO - Using connection ID 'post_s3' for task execution.
[2024-06-22T15:27:14.392+0000] {taskinstance.py:441} INFO - ::group::Post task execution logs
[2024-06-22T15:27:14.393+0000] {taskinstance.py:2905} ERROR - Task failed with exception
Traceback (most recent call last):
  File "/home/airflow/.local/lib/python3.12/site-packages/airflow/models/taskinstance.py", line 465, in _execute_task
    result = _execute_callable(context=context, **execute_callable_kwargs)
             ^^^^^^^^^^^^^^^^^^^^^^^^^^^^^^^^^^^^^^^^^^^^^^^^^^^^^^^^^^^^^
  File "/home/airflow/.local/lib/python3.12/site-packages/airflow/models/taskinstance.py", line 432, in _execute_callable
    return execute_callable(context=context, **execute_callable_kwargs)
           ^^^^^^^^^^^^^^^^^^^^^^^^^^^^^^^^^^^^^^^^^^^^^^^^^^^^^^^^^^^^
  File "/home/airflow/.local/lib/python3.12/site-packages/airflow/models/baseoperator.py", line 400, in wrapper
    return func(self, *args, **kwargs)
           ^^^^^^^^^^^^^^^^^^^^^^^^^^^
  File "/home/airflow/.local/lib/python3.12/site-packages/airflow/operators/python.py", line 235, in execute
    return_value = self.execute_callable()
                   ^^^^^^^^^^^^^^^^^^^^^^^
  File "/home/airflow/.local/lib/python3.12/site-packages/airflow/operators/python.py", line 252, in execute_callable
    return self.python_callable(*self.op_args, **self.op_kwargs)
           ^^^^^^^^^^^^^^^^^^^^^^^^^^^^^^^^^^^^^^^^^^^^^^^^^^^^^
  File "/opt/airflow/dags/postgres_s3.py", line 70, in load_to_postgres
    cursor.execute(insert_query, (
psycopg2.ProgrammingError: can't adapt type 'Series'
[2024-06-22T15:27:14.413+0000] {taskinstance.py:1206} INFO - Marking task as UP_FOR_RETRY. dag_id=postgres_to_s3, task_id=load_to_postgres, run_id=scheduled__2024-06-18T00:00:00+00:00, execution_date=20240618T000000, start_date=20240622T152633, end_date=20240622T152714
[2024-06-22T15:27:14.442+0000] {logging_mixin.py:188} WARNING - /home/***/.local/lib/python3.12/site-packages/***/utils/email.py:154 RemovedInAirflow3Warning: Fetching SMTP credentials from configuration variables will be deprecated in a future release. Please set credentials using a connection instead.
[2024-06-22T15:27:14.443+0000] {configuration.py:1050} WARNING - section/key [smtp/smtp_user] not found in config
[2024-06-22T15:27:14.443+0000] {email.py:271} INFO - Email alerting: attempt 1
[2024-06-22T15:27:14.454+0000] {configuration.py:1050} WARNING - section/key [smtp/smtp_user] not found in config
[2024-06-22T15:27:14.455+0000] {email.py:271} INFO - Email alerting: attempt 1
[2024-06-22T15:27:14.457+0000] {taskinstance.py:879} ERROR - Failed to send email to: protectorateog@gmail.com
Traceback (most recent call last):
  File "/home/airflow/.local/lib/python3.12/site-packages/airflow/models/taskinstance.py", line 2479, in _run_raw_task
    self._execute_task_with_callbacks(context, test_mode, session=session)
  File "/home/airflow/.local/lib/python3.12/site-packages/airflow/models/taskinstance.py", line 2676, in _execute_task_with_callbacks
    result = self._execute_task(context, task_orig)
             ^^^^^^^^^^^^^^^^^^^^^^^^^^^^^^^^^^^^^^
  File "/home/airflow/.local/lib/python3.12/site-packages/airflow/models/taskinstance.py", line 2701, in _execute_task
    return _execute_task(self, context, task_orig)
           ^^^^^^^^^^^^^^^^^^^^^^^^^^^^^^^^^^^^^^^
  File "/home/airflow/.local/lib/python3.12/site-packages/airflow/models/taskinstance.py", line 465, in _execute_task
    result = _execute_callable(context=context, **execute_callable_kwargs)
             ^^^^^^^^^^^^^^^^^^^^^^^^^^^^^^^^^^^^^^^^^^^^^^^^^^^^^^^^^^^^^
  File "/home/airflow/.local/lib/python3.12/site-packages/airflow/models/taskinstance.py", line 432, in _execute_callable
    return execute_callable(context=context, **execute_callable_kwargs)
           ^^^^^^^^^^^^^^^^^^^^^^^^^^^^^^^^^^^^^^^^^^^^^^^^^^^^^^^^^^^^
  File "/home/airflow/.local/lib/python3.12/site-packages/airflow/models/baseoperator.py", line 400, in wrapper
    return func(self, *args, **kwargs)
           ^^^^^^^^^^^^^^^^^^^^^^^^^^^
  File "/home/airflow/.local/lib/python3.12/site-packages/airflow/operators/python.py", line 235, in execute
    return_value = self.execute_callable()
                   ^^^^^^^^^^^^^^^^^^^^^^^
  File "/home/airflow/.local/lib/python3.12/site-packages/airflow/operators/python.py", line 252, in execute_callable
    return self.python_callable(*self.op_args, **self.op_kwargs)
           ^^^^^^^^^^^^^^^^^^^^^^^^^^^^^^^^^^^^^^^^^^^^^^^^^^^^^
  File "/opt/airflow/dags/postgres_s3.py", line 70, in load_to_postgres
    cursor.execute(insert_query, (
psycopg2.ProgrammingError: can't adapt type 'Series'

During handling of the above exception, another exception occurred:

Traceback (most recent call last):
  File "/home/airflow/.local/lib/python3.12/site-packages/airflow/models/taskinstance.py", line 1063, in _email_alert
    send_email(task.email, subject, html_content)
  File "/home/airflow/.local/lib/python3.12/site-packages/airflow/utils/email.py", line 80, in send_email
    return backend(
           ^^^^^^^^
  File "/home/airflow/.local/lib/python3.12/site-packages/airflow/utils/email.py", line 154, in send_email_smtp
    send_mime_email(e_from=mail_from, e_to=recipients, mime_msg=msg, conn_id=conn_id, dryrun=dryrun)
  File "/home/airflow/.local/lib/python3.12/site-packages/airflow/utils/email.py", line 273, in send_mime_email
    smtp_conn = _get_smtp_connection(smtp_host, smtp_port, smtp_timeout, smtp_ssl)
                ^^^^^^^^^^^^^^^^^^^^^^^^^^^^^^^^^^^^^^^^^^^^^^^^^^^^^^^^^^^^^^^^^^
  File "/home/airflow/.local/lib/python3.12/site-packages/airflow/utils/email.py", line 317, in _get_smtp_connection
    return smtplib.SMTP(host=host, port=port, timeout=timeout)
           ^^^^^^^^^^^^^^^^^^^^^^^^^^^^^^^^^^^^^^^^^^^^^^^^^^^
  File "/usr/local/lib/python3.12/smtplib.py", line 255, in __init__
    (code, msg) = self.connect(host, port)
                  ^^^^^^^^^^^^^^^^^^^^^^^^
  File "/usr/local/lib/python3.12/smtplib.py", line 341, in connect
    self.sock = self._get_socket(host, port, self.timeout)
                ^^^^^^^^^^^^^^^^^^^^^^^^^^^^^^^^^^^^^^^^^^
  File "/usr/local/lib/python3.12/smtplib.py", line 312, in _get_socket
    return socket.create_connection((host, port), timeout,
           ^^^^^^^^^^^^^^^^^^^^^^^^^^^^^^^^^^^^^^^^^^^^^^^
  File "/usr/local/lib/python3.12/socket.py", line 852, in create_connection
    raise exceptions[0]
  File "/usr/local/lib/python3.12/socket.py", line 837, in create_connection
    sock.connect(sa)
OSError: [Errno 99] Cannot assign requested address

During handling of the above exception, another exception occurred:

Traceback (most recent call last):
  File "/home/airflow/.local/lib/python3.12/site-packages/airflow/models/taskinstance.py", line 877, in _handle_failure
    task_instance.email_alert(error, failure_context["task"])
  File "/home/airflow/.local/lib/python3.12/site-packages/airflow/models/taskinstance.py", line 3163, in email_alert
    _email_alert(task_instance=self, exception=exception, task=task)
  File "/home/airflow/.local/lib/python3.12/site-packages/airflow/models/taskinstance.py", line 1065, in _email_alert
    send_email(task.email, subject, html_content_err)
  File "/home/airflow/.local/lib/python3.12/site-packages/airflow/utils/email.py", line 80, in send_email
    return backend(
           ^^^^^^^^
  File "/home/airflow/.local/lib/python3.12/site-packages/airflow/utils/email.py", line 154, in send_email_smtp
    send_mime_email(e_from=mail_from, e_to=recipients, mime_msg=msg, conn_id=conn_id, dryrun=dryrun)
  File "/home/airflow/.local/lib/python3.12/site-packages/airflow/utils/email.py", line 273, in send_mime_email
    smtp_conn = _get_smtp_connection(smtp_host, smtp_port, smtp_timeout, smtp_ssl)
                ^^^^^^^^^^^^^^^^^^^^^^^^^^^^^^^^^^^^^^^^^^^^^^^^^^^^^^^^^^^^^^^^^^
  File "/home/airflow/.local/lib/python3.12/site-packages/airflow/utils/email.py", line 317, in _get_smtp_connection
    return smtplib.SMTP(host=host, port=port, timeout=timeout)
           ^^^^^^^^^^^^^^^^^^^^^^^^^^^^^^^^^^^^^^^^^^^^^^^^^^^
  File "/usr/local/lib/python3.12/smtplib.py", line 255, in __init__
    (code, msg) = self.connect(host, port)
                  ^^^^^^^^^^^^^^^^^^^^^^^^
  File "/usr/local/lib/python3.12/smtplib.py", line 341, in connect
    self.sock = self._get_socket(host, port, self.timeout)
                ^^^^^^^^^^^^^^^^^^^^^^^^^^^^^^^^^^^^^^^^^^
  File "/usr/local/lib/python3.12/smtplib.py", line 312, in _get_socket
    return socket.create_connection((host, port), timeout,
           ^^^^^^^^^^^^^^^^^^^^^^^^^^^^^^^^^^^^^^^^^^^^^^^
  File "/usr/local/lib/python3.12/socket.py", line 852, in create_connection
    raise exceptions[0]
  File "/usr/local/lib/python3.12/socket.py", line 837, in create_connection
    sock.connect(sa)
OSError: [Errno 99] Cannot assign requested address
[2024-06-22T15:27:18.247+0000] {standard_task_runner.py:110} ERROR - Failed to execute job 23 for task load_to_postgres (can't adapt type 'Series'; 3926)
[2024-06-22T15:27:18.968+0000] {local_task_job_runner.py:240} INFO - Task exited with return code 1
[2024-06-22T15:27:19.025+0000] {taskinstance.py:3498} INFO - 0 downstream tasks scheduled from follow-on schedule check
[2024-06-22T15:27:20.087+0000] {local_task_job_runner.py:222} INFO - ::endgroup::
