[2024-06-16T10:18:14.195+0000] {task_context_logger.py:104} ERROR - Executor reports task instance <TaskInstance: random_user_etl.fetch_user scheduled__2024-01-01T01:13:00+00:00 [queued]> finished (failed) although the task says it's queued. (Info: None) Was the task killed externally?
