[2024-06-22T15:23:55.202+0000] {task_context_logger.py:104} ERROR - Executor reports task instance <TaskInstance: postgres_to_s3.transform scheduled__2024-06-17T00:00:00+00:00 [queued]> finished (failed) although the task says it's queued. (Info: None) Was the task killed externally?
