[2024-06-15T20:47:36.325+0000] {task_context_logger.py:104} ERROR - Executor reports task instance <TaskInstance: random_api.get_request scheduled__2024-06-15T19:05:00+00:00 [queued]> finished (failed) although the task says it's queued. (Info: None) Was the task killed externally?
