[2024-06-17T09:01:50.392+0000] {task_context_logger.py:104} ERROR - Executor reports task instance <TaskInstance: postgres_to_s3.fetch_user manual__2024-06-17T08:56:08.856496+00:00 [queued]> finished (failed) although the task says it's queued. (Info: None) Was the task killed externally?
